Workbook

Sheet Dashboard
A1: WhatsApp Campaign Dashboard
A2: Face + Weight Rs. 499 campaign tracker for GardenSuite. Update statuses in the WhatsApp Tracker tab.
A4: Total leads | B4: Send list | C4: Sent | D4: Interested | E4: Clicked | F4: Demo booked | G4: Follow-up due | H4: Bad or check no.
A5: =COUNTA('WhatsApp Tracker'!A2:A500) -> 499 | B5: =COUNTIF('WhatsApp Tracker'!L2:L500,"Send") -> 115 | C5: =COUNTIF('WhatsApp Tracker'!T2:T500,"Sent")+COUNTIF('WhatsApp Tracker'!T2:T500,"Delivered")+COUNTIF('WhatsApp Tracker'!T2:T500,"Read") -> 31 | D5: =COUNTIF('WhatsApp Tracker'!U2:U500,"Interested")+COUNTIF('WhatsApp Tracker'!U2:U500,"Demo booked") -> 1 | E5: =COUNTIF('WhatsApp Tracker'!V2:V500,"Yes") -> 0 | F5: =COUNTIF('WhatsApp Tracker'!W2:W500,"Booked")+COUNTIF('WhatsApp Tracker'!U2:U500,"Demo booked") -> 1 | G5: =COUNTIFS('WhatsApp Tracker'!X2:X500,"<="&TODAY(),'WhatsApp Tracker'!X2:X500,">0",'WhatsApp Tracker'!Y2:Y500,"") -> 0 | H5: =COUNTIF('WhatsApp Tracker'!K2:K500,"Check")+COUNTIF('WhatsApp Tracker'!U2:U500,"Bad number") -> 1
A8: Send Funnel | D8: Reply Breakdown | G8: Action Queue
A9: Status | B9: Count | D9: Status | E9: Count | G9: Status | H9: Count
A10: Not sent | B10: =COUNTIF('WhatsApp Tracker'!T2:T500,"Not sent") -> 464 | D10: No reply | E10: =COUNTIF('WhatsApp Tracker'!U2:U500,"No reply") -> 0 | G10: Send WhatsApp | H10: =COUNTIF('WhatsApp Tracker'!AA2:AA500,"Send WhatsApp") -> 80
A11: Sent | B11: =COUNTIF('WhatsApp Tracker'!T2:T500,"Sent") -> 6 | D11: Replied | E11: =COUNTIF('WhatsApp Tracker'!U2:U500,"Replied") -> 0 | G11: Send follow-up | H11: =COUNTIF('WhatsApp Tracker'!AA2:AA500,"Send follow-up") -> 0
A12: Delivered | B12: =COUNTIF('WhatsApp Tracker'!T2:T500,"Delivered") -> 24 | D12: Interested | E12: =COUNTIF('WhatsApp Tracker'!U2:U500,"Interested") -> 0 | G12: Prepare demo | H12: =COUNTIF('WhatsApp Tracker'!AA2:AA500,"Prepare demo") -> 1
A13: Read | B13: =COUNTIF('WhatsApp Tracker'!T2:T500,"Read") -> 1 | D13: Demo booked | E13: =COUNTIF('WhatsApp Tracker'!U2:U500,"Demo booked") -> 1 | G13: Review | H13: =COUNTIF('WhatsApp Tracker'!AA2:AA500,"Review") -> 34
A14: Failed | B14: =COUNTIF('WhatsApp Tracker'!T2:T500,"Failed") -> 4 | D14: Not interested | E14: =COUNTIF('WhatsApp Tracker'!U2:U500,"Not interested") -> 0 | G14: Do not send | H14: =COUNTIF('WhatsApp Tracker'!AA2:AA500,"Do not send") -> 384
D17: Recommended WhatsApp message
D18: Face attendance + leaf weight for tea gardens. Starts from Rs. 499/month.* https://gardensuite.in/w/face-weight-499
A25: Color key
A26: Good / positive
A27: Pending / action needed
A28: Problem / stop
A29: In progress / response
A30: No reply

Sheet Work Queue
A1: Work Queue
A2: Sort by Sort Score ascending. Source Rank keeps Google Maps and directory contacts below direct CRM/list contacts.
A4: Sort Score | B4: Next Action | C4: Priority | D4: Source Rank | E4: Source Type | F4: Client Name | G4: Tea Garden | H4: WhatsApp Number | I4: Delivery | J4: Reply | K4: Clicked | L4: Demo | M4: Follow-up Due | N4: Verification | O4: Notes
A5: ='WhatsApp Tracker'!AH3 -> 4136 | B5: ='WhatsApp Tracker'!AA3 -> Review | C5: ='WhatsApp Tracker'!M3 -> Normal | D5: ='WhatsApp Tracker'!AN3 -> 1 | E5: ='WhatsApp Tracker'!AL3 -> Original CRM/manual campaign tracker | F5: ='WhatsApp Tracker'!B3 -> Sarojini Tea Company P.V.T L.MD | G5: ='WhatsApp Tracker'!C3 -> p baruah | H5: ='WhatsApp Tracker'!D3 -> 7002483957 | I5: ='WhatsApp Tracker'!T3 -> Sent | J5: ='WhatsApp Tracker'!U3 -> Unknown | K5: ='WhatsApp Tracker'!V3 -> Unknown | L5: ='WhatsApp Tracker'!W3 -> Not offered | M5: ='WhatsApp Tracker'!X3 | N5: ='WhatsApp Tracker'!AM3 -> Existing CRM lead | O5: ='WhatsApp Tracker'!AC3 -> 0
A6: ='WhatsApp Tracker'!AH9 -> 3136 | B6: ='WhatsApp Tracker'!AA9 -> Send WhatsApp | C6: ='WhatsApp Tracker'!M9 -> Normal | D6: ='WhatsApp Tracker'!AN9 -> 1 | E6: ='WhatsApp Tracker'!AL9 -> Original CRM/manual campaign tracker | F6: ='WhatsApp Tracker'!B9 -> Dekhari T.E ( unit 1 ) | G6: ='WhatsApp Tracker'!C9 -> 0 | H6: ='WhatsApp Tracker'!D9 -> 6001684868 | I6: ='WhatsApp Tracker'!T9 -> Not sent | J6: ='WhatsApp Tracker'!U9 -> Unknown | K6: ='WhatsApp Tracker'!V9 -> Unknown | L6: ='WhatsApp Tracker'!W9 -> Not offered | M6: ='WhatsApp Tracker'!X9 | N6: ='WhatsApp Tracker'!AM9 -> Existing CRM lead | O6: ='WhatsApp Tracker'!AC9 -> 0
A7: ='WhatsApp Tracker'!AH13 -> 3136 | B7: ='WhatsApp Tracker'!AA13 -> Send WhatsApp | C7: ='WhatsApp Tracker'!M13 -> Normal | D7: ='WhatsApp Tracker'!AN13 -> 1 | E7: ='WhatsApp Tracker'!AL13 -> Original CRM/manual campaign tracker | F7: ='WhatsApp Tracker'!B13 -> Madhuting T.E | G7: ='WhatsApp Tracker'!C13 -> 0 | H7: ='WhatsApp Tracker'!D13 -> 8876321148 | I7: ='WhatsApp Tracker'!T13 -> Not sent | J7: ='WhatsApp Tracker'!U13 -> Unknown | K7: ='WhatsApp Tracker'!V13 -> Unknown | L7: ='WhatsApp Tracker'!W13 -> Not offered | M7: ='WhatsApp Tracker'!X13 | N7: ='WhatsApp Tracker'!AM13 -> Existing CRM lead | O7: ='WhatsApp Tracker'!AC13 -> 0
A8: ='WhatsApp Tracker'!AH14 -> 3136 | B8: ='WhatsApp Tracker'!AA14 -> Send WhatsApp | C8: ='WhatsApp Tracker'!M14 -> Normal | D8: ='WhatsApp Tracker'!AN14 -> 1 | E8: ='WhatsApp Tracker'!AL14 -> Original CRM/manual campaign tracker | F8: ='WhatsApp Tracker'!B14 -> Mayajan T.E | G8: ='WhatsApp Tracker'!C14 -> 0 | H8: ='WhatsApp Tracker'!D14 -> 8876426227 | I8: ='WhatsApp Tracker'!T14 -> Not sent | J8: ='WhatsApp Tracker'!U14 -> Unknown | K8: ='WhatsApp Tracker'!V14 -> Unknown | L8: ='WhatsApp Tracker'!W14 -> Not offered | M8: ='WhatsApp Tracker'!X14 | N8: ='WhatsApp Tracker'!AM14 -> Existing CRM lead | O8: ='WhatsApp Tracker'!AC14 -> 0
A9: ='WhatsApp Tracker'!AH16 -> 4436 | B9: ='WhatsApp Tracker'!AA16 -> Review | C9: ='WhatsApp Tracker'!M16 -> Normal | D9: ='WhatsApp Tracker'!AN16 -> 4 | E9: ='WhatsApp Tracker'!AL16 -> Google Maps enrichment | F9: ='WhatsApp Tracker'!B16 -> Amulguri T.E. | G9: ='WhatsApp Tracker'!C16 -> Amulguri T.E. | H9: ='WhatsApp Tracker'!D16 -> 8011322474 | I9: ='WhatsApp Tracker'!T16 -> Delivered | J9: ='WhatsApp Tracker'!U16 -> Unknown | K9: ='WhatsApp Tracker'!V16 -> Unknown | L9: ='WhatsApp Tracker'!W16 -> Not offered | M9: ='WhatsApp Tracker'!X16 | N9: ='WhatsApp Tracker'!AM16 -> Lower priority: Maps result cannot be verified without manual check | O9: ='WhatsApp Tracker'!AC16 -> Imported from extract_garden. Confidence: High. Direct estate number list; Generated garden export. District: Dibrugarh State: Assam; Original personal number. Phone type: Other. In original list: Yes
A10: ='WhatsApp Tracker'!AH19 -> 4436 | B10: ='WhatsApp Tracker'!AA19 -> Review | C10: ='WhatsApp Tracker'!M19 -> Normal | D10: ='WhatsApp Tracker'!AN19 -> 4 | E10: ='WhatsApp Tracker'!AL19 -> Google Maps enrichment | F10: ='WhatsApp Tracker'!B19 -> Asitpur T.E. | G10: ='WhatsApp Tracker'!C19 -> Asitpur T.E. | H10: ='WhatsApp Tracker'!D19 -> 9954446448 | I10: ='WhatsApp Tracker'!T19 -> Failed | J10: ='WhatsApp Tracker'!U19 -> Unknown | K10: ='WhatsApp Tracker'!V19 -> Unknown | L10: ='WhatsApp Tracker'!W19 -> Not offered | M10: ='WhatsApp Tracker'!X19 | N10: ='WhatsApp Tracker'!AM19 -> Lower priority: Maps result cannot be verified without manual check | O10: ='WhatsApp Tracker'!AC19 -> NOT WHATSAPP NO
A11: ='WhatsApp Tracker'!AH20 -> 4436 | B11: ='WhatsApp Tracker'!AA20 -> Review | C11: ='WhatsApp Tracker'!M20 -> Normal | D11: ='WhatsApp Tracker'!AN20 -> 4 | E11: ='WhatsApp Tracker'!AL20 -> Google Maps enrichment | F11: ='WhatsApp Tracker'!B20 -> Bipinbag T.E. | G11: ='WhatsApp Tracker'!C20 -> Bipinbag T.E. | H11: ='WhatsApp Tracker'!D20 -> 6901259873 | I11: ='WhatsApp Tracker'!T20 -> Failed | J11: ='WhatsApp Tracker'!U20 -> Unknown | K11: ='WhatsApp Tracker'!V20 -> Unknown | L11: ='WhatsApp Tracker'!W20 -> Not offered | M11: ='WhatsApp Tracker'!X20 | N11: ='WhatsApp Tracker'!AM20 -> Lower priority: Maps result cannot be verified without manual check | O11: ='WhatsApp Tracker'!AC20 -> NOT WHATSAPP NO
A12: ='WhatsApp Tracker'!AH22 -> 4436 | B12: ='WhatsApp Tracker'!AA22 -> Review | C12: ='WhatsApp Tracker'!M22 -> Normal | D12: ='WhatsApp Tracker'!AN22 -> 4 | E12: ='WhatsApp Tracker'!AL22 -> Google Maps enrichment | F12: ='WhatsApp Tracker'!B22 -> Dinjan T.E. | G12: ='WhatsApp Tracker'!C22 -> Dinjan T.E. | H12: ='WhatsApp Tracker'!D22 -> 9954440448 | I12: ='WhatsApp Tracker'!T22 -> Delivered | J12: ='WhatsApp Tracker'!U22 -> Unknown | K12: ='WhatsApp Tracker'!V22 -> Unknown | L12: ='WhatsApp Tracker'!W22 -> Not offered | M12: ='WhatsApp Tracker'!X22 | N12: ='WhatsApp Tracker'!AM22 -> Lower priority: Maps result cannot be verified without manual check | O12: ='WhatsApp Tracker'!AC22 -> Imported from extract_garden. Confidence: High. Direct estate number list; Generated garden export. District: Dibrugarh State: Assam; Original personal number. Phone type: . In original list: Yes
A13: ='WhatsApp Tracker'!AH26 -> 1431 | B13: ='WhatsApp Tracker'!AA26 -> Prepare demo | C13: ='WhatsApp Tracker'!M26 -> Normal | D13: ='WhatsApp Tracker'!AN26 -> 4 | E13: ='WhatsApp Tracker'!AL26 -> Google Maps enrichment | F13: ='WhatsApp Tracker'!B26 -> Harishpur T.E. | G13: ='WhatsApp Tracker'!C26 -> Harishpur T.E. | H13: ='WhatsApp Tracker'!D26 -> 8486071764 | I13: ='WhatsApp Tracker'!T26 -> Read | J13: ='WhatsApp Tracker'!U26 -> Demo booked | K13: ='WhatsApp Tracker'!V26 -> Unknown | L13: ='WhatsApp Tracker'!W26 -> Completed | M13: ='WhatsApp Tracker'!X26 | N13: ='WhatsApp Tracker'!AM26 -> Lower priority: Maps result cannot be verified without manual check | O13: ='WhatsApp Tracker'!AC26 -> Imported from extract_garden. Confidence: High. Direct estate number list; Generated garden export. District: Dibrugarh State: Assam; Original personal number. Phone type: Other. In original list: Yes
A14: ='WhatsApp Tracker'!AH27 -> 4436 | B14: ='WhatsApp Tracker'!AA27 -> Review | C14: ='WhatsApp Tracker'!M27 -> Normal | D14: ='WhatsApp Tracker'!AN27 -> 4 | E14: ='WhatsApp Tracker'!AL27 -> Google Maps enrichment | F14: ='WhatsApp Tracker'!B27 -> Ida T.E. | G14: ='WhatsApp Tracker'!C27 -> Ida T.E. | H14: ='WhatsApp Tracker'!D27 -> 9365878796 | I14: ='WhatsApp Tracker'!T27 -> Failed | J14: ='WhatsApp Tracker'!U27 -> Unknown | K14: ='WhatsApp Tracker'!V27 -> Unknown | L14: ='WhatsApp Tracker'!W27 -> Not offered | M14: ='WhatsApp Tracker'!X27 | N14: ='WhatsApp Tracker'!AM27 -> Lower priority: Maps result cannot be verified without manual check | O14: ='WhatsApp Tracker'!AC27 -> Imported from extract_garden. Confidence: High. Direct estate number list; Generated garden export. District: Dibrugarh State: Assam; Original personal number. Phone type: Other. In original list: Yes
A15: ='WhatsApp Tracker'!AH29 -> 4436 | B15: ='WhatsApp Tracker'!AA29 -> Review | C15: ='WhatsApp Tracker'!M29 -> Normal | D15: ='WhatsApp Tracker'!AN29 -> 4 | E15: ='WhatsApp Tracker'!AL29 -> Google Maps enrichment | F15: ='WhatsApp Tracker'!B29 -> Kaliapani T.E. | G15: ='WhatsApp Tracker'!C29 -> Kaliapani T.E. | H15: ='WhatsApp Tracker'!D29 -> 7002201299 | I15: ='WhatsApp Tracker'!T29 -> Delivered | J15: ='WhatsApp Tracker'!U29 -> Unknown | K15: ='WhatsApp Tracker'!V29 -> Unknown | L15: ='WhatsApp Tracker'!W29 -> Not offered | M15: ='WhatsApp Tracker'!X29 | N15: ='WhatsApp Tracker'!AM29 -> Lower priority: Maps result cannot be verified without manual check | O15: ='WhatsApp Tracker'!AC29 -> Imported from extract_garden. Confidence: High. Direct estate number list; Generated garden export. District: Dibrugarh State: Assam; Original personal number. Phone type: . In original list: Yes
A16: ='WhatsApp Tracker'!AH30 -> 4436 | B16: ='WhatsApp Tracker'!AA30 -> Review | C16: ='WhatsApp Tracker'!M30 -> Normal | D16: ='WhatsApp Tracker'!AN30 -> 4 | E16: ='WhatsApp Tracker'!AL30 -> Google Maps enrichment | F16: ='WhatsApp Tracker'!B30 -> L. K. Tea Company Pvt. Ltd. | G16: ='WhatsApp Tracker'!C30 -> L. K. Tea Company Pvt. Ltd. | H16: ='WhatsApp Tracker'!D30 -> 9101799542 | I16: ='WhatsApp Tracker'!T30 -> Sent | J16: ='WhatsApp Tracker'!U30 -> Unknown | K16: ='WhatsApp Tracker'!V30 -> Unknown | L16: ='WhatsApp Tracker'!W30 -> Not offered | M16: ='WhatsApp Tracker'!X30 | N16: ='WhatsApp Tracker'!AM30 -> Lower priority: Maps result cannot be verified without manual check | O16: ='WhatsApp Tracker'!AC30 -> Imported from extract_garden. Confidence: High. Direct estate number list; Generated garden export. District: Dibrugarh State: Assam; Original personal number. Phone type: Landline (Dibrugarh). In original list: Yes
A17: ='WhatsApp Tracker'!AH31 -> 4436 | B17: ='WhatsApp Tracker'!AA31 -> Review | C17: ='WhatsApp Tracker'!M31 -> Normal | D17: ='WhatsApp Tracker'!AN31 -> 4 | E17: ='WhatsApp Tracker'!AL31 -> Google Maps enrichment | F17: ='WhatsApp Tracker'!B31 -> Madhuban T.E. | G17: ='WhatsApp Tracker'!C31 -> Madhuban T.E. | H17: ='WhatsApp Tracker'!D31 -> 9707897688 | I17: ='WhatsApp Tracker'!T31 -> Delivered | J17: ='WhatsApp Tracker'!U31 -> Unknown | K17: ='WhatsApp Tracker'!V31 -> Unknown | L17: ='WhatsApp Tracker'!W31 -> Not offered | M17: ='WhatsApp Tracker'!X31 | N17: ='WhatsApp Tracker'!AM31 -> Lower priority: Maps result cannot be verified without manual check | O17: ='WhatsApp Tracker'!AC31 -> Imported from extract_garden. Confidence: High. Direct estate number list; Generated garden export. District: Dibrugarh State: Assam; Original personal number. Phone type: Other. In original list: Yes
A18: ='WhatsApp Tracker'!AH32 -> 4436 | B18: ='WhatsApp Tracker'!AA32 -> Review | C18: ='WhatsApp Tracker'!M32 -> Normal | D18: ='WhatsApp Tracker'!AN32 -> 4 | E18: ='WhatsApp Tracker'!AL32 -> Google Maps enrichment | F18: ='WhatsApp Tracker'!B32 -> Moud Tea & Seed Co. Ltd. | G18: ='WhatsApp Tracker'!C32 -> Moud Tea & Seed Co. Ltd. | H18: ='WhatsApp Tracker'!D32 -> 9613282165 | I18: ='WhatsApp Tracker'!T32 -> Delivered | J18: ='WhatsApp Tracker'!U32 -> Unknown | K18: ='WhatsApp Tracker'!V32 -> Unknown | L18: ='WhatsApp Tracker'!W32 -> Not offered | M18: ='WhatsApp Tracker'!X32 | N18: ='WhatsApp Tracker'!AM32 -> Lower priority: Maps result cannot be verified without manual check | O18: ='WhatsApp Tracker'!AC32 -> Imported from extract_garden. Confidence: High. Direct estate number list; Generated garden export. District: Dibrugarh State: Assam; Original personal number. Phone type: Other. In original list: Yes
A19: ='WhatsApp Tracker'!AH37 -> 4436 | B19: ='WhatsApp Tracker'!AA37 -> Review | C19: ='WhatsApp Tracker'!M37 -> Normal | D19: ='WhatsApp Tracker'!AN37 -> 4 | E19: ='WhatsApp Tracker'!AL37 -> Google Maps enrichment | F19: ='WhatsApp Tracker'!B37 -> Sadasiva T.E. | G19: ='WhatsApp Tracker'!C37 -> Sadasiva T.E. | H19: ='WhatsApp Tracker'!D37 -> 9435031577 | I19: ='WhatsApp Tracker'!T37 -> Delivered | J19: ='WhatsApp Tracker'!U37 -> Unknown | K19: ='WhatsApp Tracker'!V37 -> Unknown | L19: ='WhatsApp Tracker'!W37 -> Not offered | M19: ='WhatsApp Tracker'!X37 | N19: ='WhatsApp Tracker'!AM37 -> Lower priority: Maps result cannot be verified without manual check | O19: ='WhatsApp Tracker'!AC37 -> Imported from extract_garden. Confidence: High. Direct estate number list; Generated garden export. District: Dibrugarh State: Assam; Original personal number. Phone type: Landline (Dibrugarh). In original list: Yes; Parsed from Assam Tea Directory row, verify before sending
A20: ='WhatsApp Tracker'!AH103 -> 3336 | B20: ='WhatsApp Tracker'!AA103 -> Send WhatsApp | C20: ='WhatsApp Tracker'!M103 -> Normal | D20: ='WhatsApp Tracker'!AN103 -> 3 | E20: ='WhatsApp Tracker'!AL103 -> Email/telephone workbook | F20: ='WhatsApp Tracker'!B103 -> NEETINNAGAR | G20: ='WhatsApp Tracker'!C103 -> NEETINNAGAR | H20: ='WhatsApp Tracker'!D103 -> 9435053486 | I20: ='WhatsApp Tracker'!T103 -> Not sent | J20: ='WhatsApp Tracker'!U103 -> Unknown | K20: ='WhatsApp Tracker'!V103 -> Unknown | L20: ='WhatsApp Tracker'!W103 -> Not offered | M20: ='WhatsApp Tracker'!X103 | N20: ='WhatsApp Tracker'!AM103 -> Medium confidence, parsed from text block | O20: ='WhatsApp Tracker'!AC103 -> Imported from extract_garden. Confidence: Medium. Parsed from text block in email/telephone workbook; Parsed from Assam Tea Directory row, verify before sending
A21: ='WhatsApp Tracker'!AH104 -> 3336 | B21: ='WhatsApp Tracker'!AA104 -> Send WhatsApp | C21: ='WhatsApp Tracker'!M104 -> Normal | D21: ='WhatsApp Tracker'!AN104 -> 3 | E21: ='WhatsApp Tracker'!AL104 -> Email/telephone workbook | F21: ='WhatsApp Tracker'!B104 -> PRABHAT | G21: ='WhatsApp Tracker'!C104 -> PRABHAT | H21: ='WhatsApp Tracker'!D104 -> 9435567873 | I21: ='WhatsApp Tracker'!T104 -> Not sent | J21: ='WhatsApp Tracker'!U104 -> Unknown | K21: ='WhatsApp Tracker'!V104 -> Unknown | L21: ='WhatsApp Tracker'!W104 -> Not offered | M21: ='WhatsApp Tracker'!X104 | N21: ='WhatsApp Tracker'!AM104 -> Medium confidence, parsed from text block | O21: ='WhatsApp Tracker'!AC104 -> Imported from extract_garden. Confidence: Medium. Parsed from text block in email/telephone workbook; Parsed from Assam Tea Directory row, verify before sending
A22: ='WhatsApp Tracker'!AH105 -> 3336 | B22: ='WhatsApp Tracker'!AA105 -> Send WhatsApp | C22: ='WhatsApp Tracker'!M105 -> Normal | D22: ='WhatsApp Tracker'!AN105 -> 3 | E22: ='WhatsApp Tracker'!AL105 -> Email/telephone workbook | F22: ='WhatsApp Tracker'!B105 -> PRABHAT | G22: ='WhatsApp Tracker'!C105 -> PRABHAT | H22: ='WhatsApp Tracker'!D105 -> 9831090900 | I22: ='WhatsApp Tracker'!T105 -> Not sent | J22: ='WhatsApp Tracker'!U105 -> Unknown | K22: ='WhatsApp Tracker'!V105 -> Unknown | L22: ='WhatsApp Tracker'!W105 -> Not offered | M22: ='WhatsApp Tracker'!X105 | N22: ='WhatsApp Tracker'!AM105 -> Medium confidence, parsed from text block | O22: ='WhatsApp Tracker'!AC105 -> Imported from extract_garden. Confidence: Medium. Parsed from text block in email/telephone workbook; Parsed from Assam Tea Directory row, verify before sending
A23: ='WhatsApp Tracker'!AH106 -> 3336 | B23: ='WhatsApp Tracker'!AA106 -> Send WhatsApp | C23: ='WhatsApp Tracker'!M106 -> Normal | D23: ='WhatsApp Tracker'!AN106 -> 3 | E23: ='WhatsApp Tracker'!AL106 -> Email/telephone workbook | F23: ='WhatsApp Tracker'!B106 -> SOTAI | G23: ='WhatsApp Tracker'!C106 -> SOTAI | H23: ='WhatsApp Tracker'!D106 -> 9864049079 | I23: ='WhatsApp Tracker'!T106 -> Not sent | J23: ='WhatsApp Tracker'!U106 -> Unknown | K23: ='WhatsApp Tracker'!V106 -> Unknown | L23: ='WhatsApp Tracker'!W106 -> Not offered | M23: ='WhatsApp Tracker'!X106 | N23: ='WhatsApp Tracker'!AM106 -> Medium confidence, parsed from text block | O23: ='WhatsApp Tracker'!AC106 -> Imported from extract_garden. Confidence: Medium. Parsed from text block in email/telephone workbook; Parsed from Assam Tea Directory row, verify before sending
A24: ='WhatsApp Tracker'!AH107 -> 3336 | B24: ='WhatsApp Tracker'!AA107 -> Send WhatsApp | C24: ='WhatsApp Tracker'!M107 -> Normal | D24: ='WhatsApp Tracker'!AN107 -> 3 | E24: ='WhatsApp Tracker'!AL107 -> Email/telephone workbook | F24: ='WhatsApp Tracker'!B107 -> DALOWJAN | G24: ='WhatsApp Tracker'!C107 -> DALOWJAN | H24: ='WhatsApp Tracker'!D107 -> 9435515703 | I24: ='WhatsApp Tracker'!T107 -> Not sent | J24: ='WhatsApp Tracker'!U107 -> Unknown | K24: ='WhatsApp Tracker'!V107 -> Unknown | L24: ='WhatsApp Tracker'!W107 -> Not offered | M24: ='WhatsApp Tracker'!X107 | N24: ='WhatsApp Tracker'!AM107 -> Medium confidence, parsed from text block | O24: ='WhatsApp Tracker'!AC107 -> Imported from extract_garden. Confidence: Medium. Parsed from text block in email/telephone workbook; Parsed from Assam Tea Directory row, verify before sending
A25: ='WhatsApp Tracker'!AH108 -> 3336 | B25: ='WhatsApp Tracker'!AA108 -> Send WhatsApp | C25: ='WhatsApp Tracker'!M108 -> Normal | D25: ='WhatsApp Tracker'!AN108 -> 3 | E25: ='WhatsApp Tracker'!AL108 -> Email/telephone workbook | F25: ='WhatsApp Tracker'!B108 -> GREEN VIEW | G25: ='WhatsApp Tracker'!C108 -> GREEN VIEW | H25: ='WhatsApp Tracker'!D108 -> 9678053864 | I25: ='WhatsApp Tracker'!T108 -> Not sent | J25: ='WhatsApp Tracker'!U108 -> Unknown | K25: ='WhatsApp Tracker'!V108 -> Unknown | L25: ='WhatsApp Tracker'!W108 -> Not offered | M25: ='WhatsApp Tracker'!X108 | N25: ='WhatsApp Tracker'!AM108 -> Medium confidence, parsed from text block | O25: ='WhatsApp Tracker'!AC108 -> Imported from extract_garden. Confidence: Medium. Parsed from text block in email/telephone workbook; Parsed from Assam Tea Directory row, verify before sending
A26: ='WhatsApp Tracker'!AH109 -> 3336 | B26: ='WhatsApp Tracker'!AA109 -> Send WhatsApp | C26: ='WhatsApp Tracker'!M109 -> Normal | D26: ='WhatsApp Tracker'!AN109 -> 3 | E26: ='WhatsApp Tracker'!AL109 -> Email/telephone workbook | F26: ='WhatsApp Tracker'!B109 -> GREEN VIEW | G26: ='WhatsApp Tracker'!C109 -> GREEN VIEW | H26: ='WhatsApp Tracker'!D109 -> 9678053082 | I26: ='WhatsApp Tracker'!T109 -> Not sent | J26: ='WhatsApp Tracker'!U109 -> Unknown | K26: ='WhatsApp Tracker'!V109 -> Unknown | L26: ='WhatsApp Tracker'!W109 -> Not offered | M26: ='WhatsApp Tracker'!X109 | N26: ='WhatsApp Tracker'!AM109 -> Medium confidence, parsed from text block | O26: ='WhatsApp Tracker'!AC109 -> Imported from extract_garden. Confidence: Medium. Parsed from text block in email/telephone workbook; Parsed from Assam Tea Directory row, verify before sending
A27: ='WhatsApp Tracker'!AH110 -> 3336 | B27: ='WhatsApp Tracker'!AA110 -> Send WhatsApp | C27: ='WhatsApp Tracker'!M110 -> Normal | D27: ='WhatsApp Tracker'!AN110 -> 3 | E27: ='WhatsApp Tracker'!AL110 -> Email/telephone workbook | F27: ='WhatsApp Tracker'!B110 -> HARISHPUR | G27: ='WhatsApp Tracker'!C110 -> HARISHPUR | H27: ='WhatsApp Tracker'!D110 -> 9435030713 | I27: ='WhatsApp Tracker'!T110 -> Not sent | J27: ='WhatsApp Tracker'!U110 -> Unknown | K27: ='WhatsApp Tracker'!V110 -> Unknown | L27: ='WhatsApp Tracker'!W110 -> Not offered | M27: ='WhatsApp Tracker'!X110 | N27: ='WhatsApp Tracker'!AM110 -> Medium confidence, parsed from text block | O27: ='WhatsApp Tracker'!AC110 -> Imported from extract_garden. Confidence: Medium. Parsed from text block in email/telephone workbook; Parsed from Assam Tea Directory row, verify before sending
A28: ='WhatsApp Tracker'!AH111 -> 3336 | B28: ='WhatsApp Tracker'!AA111 -> Send WhatsApp | C28: ='WhatsApp Tracker'!M111 -> Normal | D28: ='WhatsApp Tracker'!AN111 -> 3 | E28: ='WhatsApp Tracker'!AL111 -> Email/telephone workbook | F28: ='WhatsApp Tracker'!B111 -> MOTHOLA | G28: ='WhatsApp Tracker'!C111 -> MOTHOLA | H28: ='WhatsApp Tracker'!D111 -> 9435032117 | I28: ='WhatsApp Tracker'!T111 -> Not sent | J28: ='WhatsApp Tracker'!U111 -> Unknown | K28: ='WhatsApp Tracker'!V111 -> Unknown | L28: ='WhatsApp Tracker'!W111 -> Not offered | M28: ='WhatsApp Tracker'!X111 | N28: ='WhatsApp Tracker'!AM111 -> Medium confidence, parsed from text block | O28: ='WhatsApp Tracker'!AC111 -> Imported from extract_garden. Confidence: Medium. Parsed from text block in email/telephone workbook; Parsed from Assam Tea Directory row, verify before sending
A29: ='WhatsApp Tracker'!AH112 -> 3336 | B29: ='WhatsApp Tracker'!AA112 -> Send WhatsApp | C29: ='WhatsApp Tracker'!M112 -> Normal | D29: ='WhatsApp Tracker'!AN112 -> 3 | E29: ='WhatsApp Tracker'!AL112 -> Email/telephone workbook | F29: ='WhatsApp Tracker'!B112 -> RADHABARI | G29: ='WhatsApp Tracker'!C112 -> RADHABARI | H29: ='WhatsApp Tracker'!D112 -> 9954471732 | I29: ='WhatsApp Tracker'!T112 -> Not sent | J29: ='WhatsApp Tracker'!U112 -> Unknown | K29: ='WhatsApp Tracker'!V112 -> Unknown | L29: ='WhatsApp Tracker'!W112 -> Not offered | M29: ='WhatsApp Tracker'!X112 | N29: ='WhatsApp Tracker'!AM112 -> Medium confidence, parsed from text block | O29: ='WhatsApp Tracker'!AC112 -> Imported from extract_garden. Confidence: Medium. Parsed from text block in email/telephone workbook; Parsed from Assam Tea Directory row, verify before sending
A30: ='WhatsApp Tracker'!AH113 -> 3336 | B30: ='WhatsApp Tracker'!AA113 -> Send WhatsApp | C30: ='WhatsApp Tracker'!M113 -> Normal | D30: ='WhatsApp Tracker'!AN113 -> 3 | E30: ='WhatsApp Tracker'!AL113 -> Email/telephone workbook | F30: ='WhatsApp Tracker'!B113 -> RADHABARI | G30: ='WhatsApp Tracker'!C113 -> RADHABARI | H30: ='WhatsApp Tracker'!D113 -> 9435052701 | I30: ='WhatsApp Tracker'!T113 -> Not sent | J30: ='WhatsApp Tracker'!U113 -> Unknown | K30: ='WhatsApp Tracker'!V113 -> Unknown | L30: ='WhatsApp Tracker'!W113 -> Not offered | M30: ='WhatsApp Tracker'!X113 | N30: ='WhatsApp Tracker'!AM113 -> Medium confidence, parsed from text block | O30: ='WhatsApp Tracker'!AC113 -> Imported from extract_garden. Confidence: Medium. Parsed from text block in email/telephone workbook; Parsed from Assam Tea Directory row, verify before sending
A31: ='WhatsApp Tracker'!AH114 -> 3336 | B31: ='WhatsApp Tracker'!AA114 -> Send WhatsApp | C31: ='WhatsApp Tracker'!M114 -> Normal | D31: ='WhatsApp Tracker'!AN114 -> 3 | E31: ='WhatsApp Tracker'!AL114 -> Email/telephone workbook | F31: ='WhatsApp Tracker'!B114 -> SONARIE | G31: ='WhatsApp Tracker'!C114 -> SONARIE | H31: ='WhatsApp Tracker'!D114 -> 9954526126 | I31: ='WhatsApp Tracker'!T114 -> Not sent | J31: ='WhatsApp Tracker'!U114 -> Unknown | K31: ='WhatsApp Tracker'!V114 -> Unknown | L31: ='WhatsApp Tracker'!W114 -> Not offered | M31: ='WhatsApp Tracker'!X114 | N31: ='WhatsApp Tracker'!AM114 -> Medium confidence, parsed from text block | O31: ='WhatsApp Tracker'!AC114 -> Imported from extract_garden. Confidence: Medium. Parsed from text block in email/telephone workbook; Parsed from Assam Tea Directory row, verify before sending
... A56: ='WhatsApp Tracker'!AH139 -> 9596 | B56: ='WhatsApp Tracker'!AA139 -> Do not send | C56: ='WhatsApp Tracker'!M139 -> Hold | D56: ='WhatsApp Tracker'!AN139 -> 5 | E56: ='WhatsApp Tracker'!AL139 -> Parsed directory row | F56: ='WhatsApp Tracker'!B139 -> Imported contact | G56: ='WhatsApp Tracker'!C139 -> 0 | H56: ='WhatsApp Tracker'!D139 -> 9830250055 | I56: ='WhatsApp Tracker'!T139 -> Not sent | J56: ='WhatsApp Tracker'!U139 -> Unknown | K56: ='WhatsApp Tracker'!V139 -> Unknown | L56: ='WhatsApp Tracker'!W139 -> Not offered | M56: ='WhatsApp Tracker'!X139 | N56: ='WhatsApp Tracker'!AM139 -> Low confidence: verify before sending | O56: ='WhatsApp Tracker'!AC139 -> Imported from extract_garden. Confidence: Low. Parsed from Assam Tea Directory row, verify before sending
A57: ='WhatsApp Tracker'!AH40 -> 4436 | B57: ='WhatsApp Tracker'!AA40 -> Review | C57: ='WhatsApp Tracker'!M40 -> Normal | D57: ='WhatsApp Tracker'!AN40 -> 4 | E57: ='WhatsApp Tracker'!AL40 -> Google Maps enrichment | F57: ='WhatsApp Tracker'!B40 -> Satkarter T.E. | G57: ='WhatsApp Tracker'!C40 -> Satkarter T.E. | H57: ='WhatsApp Tracker'!D40 -> 9435033023 | I57: ='WhatsApp Tracker'!T40 -> Delivered | J57: ='WhatsApp Tracker'!U40 -> Unknown | K57: ='WhatsApp Tracker'!V40 -> Unknown | L57: ='WhatsApp Tracker'!W40 -> Not offered | M57: ='WhatsApp Tracker'!X40 | N57: ='WhatsApp Tracker'!AM40 -> Lower priority: Maps result cannot be verified without manual check | O57: ='WhatsApp Tracker'!AC40 -> Imported from extract_garden. Confidence: High. Direct estate number list; Generated garden export. District: Dibrugarh State: Assam; Original personal number. Phone type: Other. In original list: Yes
A58: ='WhatsApp Tracker'!AH41 -> 4436 | B58: ='WhatsApp Tracker'!AA41 -> Review | C58: ='WhatsApp Tracker'!M41 -> Normal | D58: ='WhatsApp Tracker'!AN41 -> 4 | E58: ='WhatsApp Tracker'!AL41 -> Google Maps enrichment | F58: ='WhatsApp Tracker'!B41 -> Satyanarayana T.E. | G58: ='WhatsApp Tracker'!C41 -> Satyanarayana T.E. | H58: ='WhatsApp Tracker'!D41 -> 8011018074 | I58: ='WhatsApp Tracker'!T41 -> Delivered | J58: ='WhatsApp Tracker'!U41 -> Unknown | K58: ='WhatsApp Tracker'!V41 -> Unknown | L58: ='WhatsApp Tracker'!W41 -> Not offered | M58: ='WhatsApp Tracker'!X41 | N58: ='WhatsApp Tracker'!AM41 -> Lower priority: Maps result cannot be verified without manual check | O58: ='WhatsApp Tracker'!AC41 -> Imported from extract_garden. Confidence: High. Direct estate number list; Generated garden export. District: Dibrugarh State: Assam; Original personal number. Phone type: Other. In original list: Yes
A59: ='WhatsApp Tracker'!AH42 -> 4436 | B59: ='WhatsApp Tracker'!AA42 -> Review | C59: ='WhatsApp Tracker'!M42 -> Normal | D59: ='WhatsApp Tracker'!AN42 -> 4 | E59: ='WhatsApp Tracker'!AL42 -> Google Maps enrichment | F59: ='WhatsApp Tracker'!B42 -> Suraj T.E. | G59: ='WhatsApp Tracker'!C42 -> Suraj T.E. | H59: ='WhatsApp Tracker'!D42 -> 9401129574 | I59: ='WhatsApp Tracker'!T42 -> Delivered | J59: ='WhatsApp Tracker'!U42 -> Unknown | K59: ='WhatsApp Tracker'!V42 -> Unknown | L59: ='WhatsApp Tracker'!W42 -> Not offered | M59: ='WhatsApp Tracker'!X42 | N59: ='WhatsApp Tracker'!AM42 -> Lower priority: Maps result cannot be verified without manual check | O59: ='WhatsApp Tracker'!AC42 -> Imported from extract_garden. Confidence: High. Direct estate number list; Generated garden export. District: Dibrugarh State: Assam; Original personal number. Phone type: Other. In original list: Yes
A60: ='WhatsApp Tracker'!AH43 -> 4436 | B60: ='WhatsApp Tracker'!AA43 -> Review | C60: ='WhatsApp Tracker'!M43 -> Normal | D60: ='WhatsApp Tracker'!AN43 -> 4 | E60: ='WhatsApp Tracker'!AL43 -> Google Maps enrichment | F60: ='WhatsApp Tracker'!B43 -> Triveni T.E. | G60: ='WhatsApp Tracker'!C43 -> Triveni T.E. | H60: ='WhatsApp Tracker'!D43 -> 9435532002 | I60: ='WhatsApp Tracker'!T43 -> Delivered | J60: ='WhatsApp Tracker'!U43 -> Unknown | K60: ='WhatsApp Tracker'!V43 -> Unknown | L60: ='WhatsApp Tracker'!W43 -> Not offered | M60: ='WhatsApp Tracker'!X43 | N60: ='WhatsApp Tracker'!AM43 -> Lower priority: Maps result cannot be verified without manual check | O60: ='WhatsApp Tracker'!AC43 -> Imported from extract_garden. Confidence: High. Direct estate number list; Generated garden export. District: Dibrugarh State: Assam; Original personal number. Phone type: Other. In original list: Yes
A61: ='WhatsApp Tracker'!AH44 -> 4436 | B61: ='WhatsApp Tracker'!AA44 -> Review | C61: ='WhatsApp Tracker'!M44 -> Normal | D61: ='WhatsApp Tracker'!AN44 -> 4 | E61: ='WhatsApp Tracker'!AL44 -> Google Maps enrichment | F61: ='WhatsApp Tracker'!B44 -> Udalguri T.E. | G61: ='WhatsApp Tracker'!C44 -> Udalguri T.E. | H61: ='WhatsApp Tracker'!D44 -> 9954447408 | I61: ='WhatsApp Tracker'!T44 -> Sent | J61: ='WhatsApp Tracker'!U44 -> Unknown | K61: ='WhatsApp Tracker'!V44 -> Unknown | L61: ='WhatsApp Tracker'!W44 -> Not offered | M61: ='WhatsApp Tracker'!X44 | N61: ='WhatsApp Tracker'!AM44 -> Lower priority: Maps result cannot be verified without manual check | O61: ='WhatsApp Tracker'!AC44 -> Imported from extract_garden. Confidence: High. Direct estate number list; Generated garden export. District: Dibrugarh State: Assam; Original personal number. Phone type: . In original list: Yes
A62: ='WhatsApp Tracker'!AH45 -> 4436 | B62: ='WhatsApp Tracker'!AA45 -> Review | C62: ='WhatsApp Tracker'!M45 -> Normal | D62: ='WhatsApp Tracker'!AN45 -> 4 | E62: ='WhatsApp Tracker'!AL45 -> Google Maps enrichment | F62: ='WhatsApp Tracker'!B45 -> Homestay by the Tea Garden, Dibrugarh | G62: ='WhatsApp Tracker'!C45 -> Ahmedy T.E. | H62: ='WhatsApp Tracker'!D45 -> 9899997370 | I62: ='WhatsApp Tracker'!T45 -> Delivered | J62: ='WhatsApp Tracker'!U45 -> Unknown | K62: ='WhatsApp Tracker'!V45 -> Unknown | L62: ='WhatsApp Tracker'!W45 -> Not offered | M62: ='WhatsApp Tracker'!X45 | N62: ='WhatsApp Tracker'!AM45 -> Lower priority: Maps result cannot be verified without manual check | O62: ='WhatsApp Tracker'!AC45 -> Imported from extract_garden. Confidence: Medium. Google Maps phone. Phone type: Other. In original list: No; Google Maps phone. Phone type: Other. In original list: Yes
A63: ='WhatsApp Tracker'!AH46 -> 4436 | B63: ='WhatsApp Tracker'!AA46 -> Review | C63: ='WhatsApp Tracker'!M46 -> Normal | D63: ='WhatsApp Tracker'!AN46 -> 4 | E63: ='WhatsApp Tracker'!AL46 -> Google Maps enrichment | F63: ='WhatsApp Tracker'!B46 -> ALIMUR SWEETS | G63: ='WhatsApp Tracker'!C46 -> Alimur T.E. | H63: ='WhatsApp Tracker'!D46 -> 8011162497 | I63: ='WhatsApp Tracker'!T46 -> Sent | J63: ='WhatsApp Tracker'!U46 -> Unknown | K63: ='WhatsApp Tracker'!V46 -> Unknown | L63: ='WhatsApp Tracker'!W46 -> Not offered | M63: ='WhatsApp Tracker'!X46 | N63: ='WhatsApp Tracker'!AM46 -> Lower priority: Maps result cannot be verified without manual check | O63: ='WhatsApp Tracker'!AC46 -> Imported from extract_garden. Confidence: Medium. Google Maps phone. Phone type: Other. In original list: Yes
A64: ='WhatsApp Tracker'!AH47 -> 4436 | B64: ='WhatsApp Tracker'!AA47 -> Review | C64: ='WhatsApp Tracker'!M47 -> Normal | D64: ='WhatsApp Tracker'!AN47 -> 4 | E64: ='WhatsApp Tracker'!AL47 -> Google Maps enrichment | F64: ='WhatsApp Tracker'!B47 -> APARNA STORE | G64: ='WhatsApp Tracker'!C47 -> Aparna T.E. | H64: ='WhatsApp Tracker'!D47 -> 9395836442 | I64: ='WhatsApp Tracker'!T47 -> Delivered | J64: ='WhatsApp Tracker'!U47 -> Unknown | K64: ='WhatsApp Tracker'!V47 -> Unknown | L64: ='WhatsApp Tracker'!W47 -> Not offered | M64: ='WhatsApp Tracker'!X47 | N64: ='WhatsApp Tracker'!AM47 -> Lower priority: Maps result cannot be verified without manual check | O64: ='WhatsApp Tracker'!AC47 -> Imported from extract_garden. Confidence: Medium. Google Maps phone. Phone type: Other. In original list: Yes
A65: ='WhatsApp Tracker'!AH48 -> 3436 | B65: ='WhatsApp Tracker'!AA48 -> Send WhatsApp | C65: ='WhatsApp Tracker'!M48 -> Normal | D65: ='WhatsApp Tracker'!AN48 -> 4 | E65: ='WhatsApp Tracker'!AL48 -> Google Maps enrichment | F65: ='WhatsApp Tracker'!B48 -> Mancotta Tea Estate Garden | G65: ='WhatsApp Tracker'!C48 -> Asitpur T.E. | H65: ='WhatsApp Tracker'!D48 -> 9395331162 | I65: ='WhatsApp Tracker'!T48 -> Not sent | J65: ='WhatsApp Tracker'!U48 -> Unknown | K65: ='WhatsApp Tracker'!V48 -> Unknown | L65: ='WhatsApp Tracker'!W48 -> Not offered | M65: ='WhatsApp Tracker'!X48 | N65: ='WhatsApp Tracker'!AM48 -> Lower priority: Maps result cannot be verified without manual check | O65: ='WhatsApp Tracker'!AC48 -> Imported from extract_garden. Confidence: Medium. Google Maps phone. Phone type: Other. In original list: Yes; Google Maps phone. Phone type: Other. In original list: No
...

Sheet WhatsApp Tracker
A1: Lead ID | B1: Client Name | C1: Tea Garden | D1: WhatsApp Number | E1: Workers | F1: Original CRM Status | G1: Original Next Follow-up | H1: Created | I1: Original Remarks | J1: Extra Note | K1: Phone OK | L1: Send Decision | M1: Priority | N1: Campaign | O1: Message Variant | P1: Image/Preview | Q1: Share Link | R1: First Sent Date | S1: Sent By | T1: Delivery Status | U1: Reply Status | V1: Clicked Link | W1: Demo Call Status | X1: Follow-up Due | Y1: Follow-up Sent Date | Z1: Final Outcome | AA1: Next Action | AB1: Owner | AC1: Campaign Notes | AD1: Work Rank | AE1: Priority Rank | AF1: Delivery Rank | AG1: Reply Rank | AH1: Sort Score | AI1: Last Touch | AJ1: Follow-up State | AK1: Data Source | AL1: Source Type | AM1: Verification | AN1: Source Rank | AO1: WA Check Link | AP1: WA Check Status | AQ1: WA Checked At | AR1: WA Check Notes
A2: GSW019 | B2: Hatijan T.E | D2: 9365634055 | F2: Negotiation | G2: 46147 | H2: 46139 | I2: call pending | K2: =IF(LEN(D2)=10,"OK","Check") -> OK | L2: =IF(ISNUMBER(SEARCH("not interested",LOWER(I2&" "&J2))),"Hold","Send") -> Send | M2: =IF(L2="Hold","Hold",IF(IFERROR(E2,0)>=200,"High",IF(IFERROR(E2,0)>=100,"Medium","Normal"))) -> Normal | N2: Face + Weight Rs. 499 WhatsApp | O2: Price hook | P2: Price v4 | Q2: https://gardensuite.in/w/face-weight-499 | T2: Sent | U2: Unknown | V2: Unknown | W2: Not offered | X2: =IF(AND(R2<>"",OR(U2="No reply",U2="Unknown")),R2+2,"") | Z2: Open | AA2: =IF(L2="Hold","Do not send",IF(T2="Not sent","Send WhatsApp",IF(U2="Demo booked","Prepare demo",IF(W2="Booked","Prepare demo",IF(AND(X2<>"",Y2=""),"Send follow-up","Review"))))) -> Review | AD2: =IF(AA2="Prepare demo",1,IF(AA2="Send follow-up",2,IF(AA2="Send WhatsApp",3,IF(AA2="Review",4,IF(AA2="Do not send",9,5))))) -> 4 | AE2: =IF(M2="High",1,IF(M2="Medium",2,IF(M2="Normal",3,IF(M2="Hold",9,4)))) -> 3 | AF2: =IF(T2="Read",1,IF(T2="Delivered",2,IF(T2="Sent",3,IF(T2="Not sent",4,IF(T2="Failed",9,5))))) -> 3 | AG2: =IF(U2="Demo booked",1,IF(U2="Interested",2,IF(U2="Replied",3,IF(U2="No reply",5,IF(U2="Not interested",8,IF(U2="Bad number",9,6)))))) -> 6 | AH2: =AD2*1000+AN2*100+AE2*10+AG2 -> 4136 | AI2: =MAX(IF(R2="",0,R2),IF(Y2="",0,Y2)) -> 0 | AJ2: =IF(AND(X2<>"",Y2="",X2<TODAY()),"Overdue",IF(AND(X2<>"",Y2="",X2=TODAY()),"Due today",IF(Y2<>"","Follow-up sent",""))) | AK2: Original CRM | AL2: Original CRM/manual campaign tracker | AM2: Existing CRM lead | AN2: 1 | AO2: https://wa.me/919365634055 | AP2: Login required | AQ2: 46161.629 | AR2: WhatsApp Web login required, scan QR and rerun
A3: GSW006 | B3: Sarojini Tea Company P.V.T L.MD | C3: p baruah | D3: 7002483957 | F3: Negotiation | G3: 46127 | H3: 46130 | I3: call pending | K3: =IF(LEN(D3)=10,"OK","Check") -> OK | L3: =IF(ISNUMBER(SEARCH("not interested",LOWER(I3&" "&J3))),"Hold","Send") -> Send | M3: =IF(L3="Hold","Hold",IF(IFERROR(E3,0)>=200,"High",IF(IFERROR(E3,0)>=100,"Medium","Normal"))) -> Normal | N3: Face + Weight Rs. 499 WhatsApp | O3: Price hook | P3: Price v4 | Q3: https://gardensuite.in/w/face-weight-499 | T3: Sent | U3: Unknown | V3: Unknown | W3: Not offered | X3: =IF(AND(R3<>"",OR(U3="No reply",U3="Unknown")),R3+2,"") | Z3: Open | AA3: =IF(L3="Hold","Do not send",IF(T3="Not sent","Send WhatsApp",IF(U3="Demo booked","Prepare demo",IF(W3="Booked","Prepare demo",IF(AND(X3<>"",Y3=""),"Send follow-up","Review"))))) -> Review | AD3: =IF(AA3="Prepare demo",1,IF(AA3="Send follow-up",2,IF(AA3="Send WhatsApp",3,IF(AA3="Review",4,IF(AA3="Do not send",9,5))))) -> 4 | AE3: =IF(M3="High",1,IF(M3="Medium",2,IF(M3="Normal",3,IF(M3="Hold",9,4)))) -> 3 | AF3: =IF(T3="Read",1,IF(T3="Delivered",2,IF(T3="Sent",3,IF(T3="Not sent",4,IF(T3="Failed",9,5))))) -> 3 | AG3: =IF(U3="Demo booked",1,IF(U3="Interested",2,IF(U3="Replied",3,IF(U3="No reply",5,IF(U3="Not interested",8,IF(U3="Bad number",9,6)))))) -> 6 | AH3: =AD3*1000+AN3*100+AE3*10+AG3 -> 4136 | AI3: =MAX(IF(R3="",0,R3),IF(Y3="",0,Y3)) -> 0 | AJ3: =IF(AND(X3<>"",Y3="",X3<TODAY()),"Overdue",IF(AND(X3<>"",Y3="",X3=TODAY()),"Due today",IF(Y3<>"","Follow-up sent",""))) | AK3: Original CRM | AL3: Original CRM/manual campaign tracker | AM3: Existing CRM lead | AN3: 1 | AO3: https://wa.me/917002483957 | AP3: Login required | AQ3: 46161.626 | AR3: WhatsApp Web login required, scan QR and rerun
A4: GSW034 | B4: Topojit Bagchi | C4: Phukenbari T. E | D4: 7002398813 | E4: 300 | F4: Negotiation | G4: 46154 | H4: 46130 | I4: NOT WHATSAPP NO | K4: =IF(LEN(D4)=10,"OK","Check") -> OK | L4: =IF(ISNUMBER(SEARCH("not interested",LOWER(I4&" "&J4))),"Hold","Send") -> Send | M4: =IF(L4="Hold","Hold",IF(IFERROR(E4,0)>=200,"High",IF(IFERROR(E4,0)>=100,"Medium","Normal"))) -> High | N4: Face + Weight Rs. 499 WhatsApp | O4: Price hook | P4: Price v4 | Q4: https://gardensuite.in/w/face-weight-499 | T4: Not sent | U4: Unknown | V4: Unknown | W4: Not offered | X4: =IF(AND(R4<>"",OR(U4="No reply",U4="Unknown")),R4+2,"") | Z4: Open | AA4: =IF(L4="Hold","Do not send",IF(T4="Not sent","Send WhatsApp",IF(U4="Demo booked","Prepare demo",IF(W4="Booked","Prepare demo",IF(AND(X4<>"",Y4=""),"Send follow-up","Review"))))) -> Send WhatsApp | AD4: =IF(AA4="Prepare demo",1,IF(AA4="Send follow-up",2,IF(AA4="Send WhatsApp",3,IF(AA4="Review",4,IF(AA4="Do not send",9,5))))) -> 3 | AE4: =IF(M4="High",1,IF(M4="Medium",2,IF(M4="Normal",3,IF(M4="Hold",9,4)))) -> 1 | AF4: =IF(T4="Read",1,IF(T4="Delivered",2,IF(T4="Sent",3,IF(T4="Not sent",4,IF(T4="Failed",9,5))))) -> 4 | AG4: =IF(U4="Demo booked",1,IF(U4="Interested",2,IF(U4="Replied",3,IF(U4="No reply",5,IF(U4="Not interested",8,IF(U4="Bad number",9,6)))))) -> 6 | AH4: =AD4*1000+AN4*100+AE4*10+AG4 -> 3116 | AI4: =MAX(IF(R4="",0,R4),IF(Y4="",0,Y4)) -> 0 | AJ4: =IF(AND(X4<>"",Y4="",X4<TODAY()),"Overdue",IF(AND(X4<>"",Y4="",X4=TODAY()),"Due today",IF(Y4<>"","Follow-up sent",""))) | AK4: Original CRM | AL4: Original CRM/manual campaign tracker | AM4: Existing CRM lead | AN4: 1 | AO4: https://wa.me/917002398813 | AP4: Login required | AQ4: 46161.624 | AR4: WhatsApp Web login required, scan QR and rerun
A5: GSW002 | B5: Durgapur T.E | D5: 8638867855 | F5: Negotiation | G5: 46118 | H5: 46136 | I5: NOT WHATSAPP NO | K5: =IF(LEN(D5)=10,"OK","Check") -> OK | L5: =IF(ISNUMBER(SEARCH("not interested",LOWER(I5&" "&J5))),"Hold","Send") -> Send | M5: =IF(L5="Hold","Hold",IF(IFERROR(E5,0)>=200,"High",IF(IFERROR(E5,0)>=100,"Medium","Normal"))) -> Normal | N5: Face + Weight Rs. 499 WhatsApp | O5: Price hook | P5: Price v4 | Q5: https://gardensuite.in/w/face-weight-499 | T5: Not sent | U5: Unknown | V5: Unknown | W5: Not offered | X5: =IF(AND(R5<>"",OR(U5="No reply",U5="Unknown")),R5+2,"") | Z5: Open | AA5: =IF(L5="Hold","Do not send",IF(T5="Not sent","Send WhatsApp",IF(U5="Demo booked","Prepare demo",IF(W5="Booked","Prepare demo",IF(AND(X5<>"",Y5=""),"Send follow-up","Review"))))) -> Send WhatsApp | AD5: =IF(AA5="Prepare demo",1,IF(AA5="Send follow-up",2,IF(AA5="Send WhatsApp",3,IF(AA5="Review",4,IF(AA5="Do not send",9,5))))) -> 3 | AE5: =IF(M5="High",1,IF(M5="Medium",2,IF(M5="Normal",3,IF(M5="Hold",9,4)))) -> 3 | AF5: =IF(T5="Read",1,IF(T5="Delivered",2,IF(T5="Sent",3,IF(T5="Not sent",4,IF(T5="Failed",9,5))))) -> 4 | AG5: =IF(U5="Demo booked",1,IF(U5="Interested",2,IF(U5="Replied",3,IF(U5="No reply",5,IF(U5="Not interested",8,IF(U5="Bad number",9,6)))))) -> 6 | AH5: =AD5*1000+AN5*100+AE5*10+AG5 -> 3136 | AI5: =MAX(IF(R5="",0,R5),IF(Y5="",0,Y5)) -> 0 | AJ5: =IF(AND(X5<>"",Y5="",X5<TODAY()),"Overdue",IF(AND(X5<>"",Y5="",X5=TODAY()),"Due today",IF(Y5<>"","Follow-up sent",""))) | AK5: Original CRM | AL5: Original CRM/manual campaign tracker | AM5: Existing CRM lead | AN5: 1 | AO5: https://wa.me/918638867855 | AP5: Login required | AQ5: 46161.625 | AR5: WhatsApp Web login required, scan QR and rerun
A6: GSW008 | B6: Kothalguri T.E | D6: 8876321148 | F6: Negotiation | G6: 46140 | H6: 46139 | I6: NOT WHATSAPP NO | K6: =IF(LEN(D6)=10,"OK","Check") -> OK | L6: =IF(ISNUMBER(SEARCH("not interested",LOWER(I6&" "&J6))),"Hold","Send") -> Send | M6: =IF(L6="Hold","Hold",IF(IFERROR(E6,0)>=200,"High",IF(IFERROR(E6,0)>=100,"Medium","Normal"))) -> Normal | N6: Face + Weight Rs. 499 WhatsApp | O6: Price hook | P6: Price v4 | Q6: https://gardensuite.in/w/face-weight-499 | T6: Not sent | U6: Unknown | V6: Unknown | W6: Not offered | X6: =IF(AND(R6<>"",OR(U6="No reply",U6="Unknown")),R6+2,"") | Z6: Open | AA6: =IF(L6="Hold","Do not send",IF(T6="Not sent","Send WhatsApp",IF(U6="Demo booked","Prepare demo",IF(W6="Booked","Prepare demo",IF(AND(X6<>"",Y6=""),"Send follow-up","Review"))))) -> Send WhatsApp | AD6: =IF(AA6="Prepare demo",1,IF(AA6="Send follow-up",2,IF(AA6="Send WhatsApp",3,IF(AA6="Review",4,IF(AA6="Do not send",9,5))))) -> 3 | AE6: =IF(M6="High",1,IF(M6="Medium",2,IF(M6="Normal",3,IF(M6="Hold",9,4)))) -> 3 | AF6: =IF(T6="Read",1,IF(T6="Delivered",2,IF(T6="Sent",3,IF(T6="Not sent",4,IF(T6="Failed",9,5))))) -> 4 | AG6: =IF(U6="Demo booked",1,IF(U6="Interested",2,IF(U6="Replied",3,IF(U6="No reply",5,IF(U6="Not interested",8,IF(U6="Bad number",9,6)))))) -> 6 | AH6: =AD6*1000+AN6*100+AE6*10+AG6 -> 3136 | AI6: =MAX(IF(R6="",0,R6),IF(Y6="",0,Y6)) -> 0 | AJ6: =IF(AND(X6<>"",Y6="",X6<TODAY()),"Overdue",IF(AND(X6<>"",Y6="",X6=TODAY()),"Due today",IF(Y6<>"","Follow-up sent",""))) | AK6: Original CRM | AL6: Original CRM/manual campaign tracker | AM6: Existing CRM lead | AN6: 1 | AO6: https://wa.me/918876321148 | AP6: Login required | AQ6: 46161.63 | AR6: WhatsApp Web login required, scan QR and rerun
A7: GSW009 | B7: Balimara T.E | C7: Balimara T.E | D7: 9435738646 | F7: Negotiation | G7: 46146 | H7: 46136 | I7: NOT WHATSAPP NO | K7: =IF(LEN(D7)=10,"OK","Check") -> OK | L7: =IF(ISNUMBER(SEARCH("not interested",LOWER(I7&" "&J7))),"Hold","Send") -> Send | M7: =IF(L7="Hold","Hold",IF(IFERROR(E7,0)>=200,"High",IF(IFERROR(E7,0)>=100,"Medium","Normal"))) -> Normal | N7: Face + Weight Rs. 499 WhatsApp | O7: Price hook | P7: Price v4 | Q7: https://gardensuite.in/w/face-weight-499 | T7: Not sent | U7: Unknown | V7: Unknown | W7: Not offered | X7: =IF(AND(R7<>"",OR(U7="No reply",U7="Unknown")),R7+2,"") | Z7: Open | AA7: =IF(L7="Hold","Do not send",IF(T7="Not sent","Send WhatsApp",IF(U7="Demo booked","Prepare demo",IF(W7="Booked","Prepare demo",IF(AND(X7<>"",Y7=""),"Send follow-up","Review"))))) -> Send WhatsApp | AD7: =IF(AA7="Prepare demo",1,IF(AA7="Send follow-up",2,IF(AA7="Send WhatsApp",3,IF(AA7="Review",4,IF(AA7="Do not send",9,5))))) -> 3 | AE7: =IF(M7="High",1,IF(M7="Medium",2,IF(M7="Normal",3,IF(M7="Hold",9,4)))) -> 3 | AF7: =IF(T7="Read",1,IF(T7="Delivered",2,IF(T7="Sent",3,IF(T7="Not sent",4,IF(T7="Failed",9,5))))) -> 4 | AG7: =IF(U7="Demo booked",1,IF(U7="Interested",2,IF(U7="Replied",3,IF(U7="No reply",5,IF(U7="Not interested",8,IF(U7="Bad number",9,6)))))) -> 6 | AH7: =AD7*1000+AN7*100+AE7*10+AG7 -> 3136 | AI7: =MAX(IF(R7="",0,R7),IF(Y7="",0,Y7)) -> 0 | AJ7: =IF(AND(X7<>"",Y7="",X7<TODAY()),"Overdue",IF(AND(X7<>"",Y7="",X7=TODAY()),"Due today",IF(Y7<>"","Follow-up sent",""))) | AK7: Original CRM | AL7: Original CRM/manual campaign tracker | AM7: Existing CRM lead | AN7: 1 | AO7: https://wa.me/919435738646 | AP7: Login required | AQ7: 46161.627 | AR7: WhatsApp Web login required, scan QR and rerun
A8: GSW012 | B8: Dekhari T.E | D8: 9101006460 | F8: Negotiation | G8: 46146 | H8: 46136 | I8: INVALID NUMBER | K8: =IF(LEN(D8)=10,"OK","Check") -> OK | L8: =IF(ISNUMBER(SEARCH("not interested",LOWER(I8&" "&J8))),"Hold","Send") -> Send | M8: =IF(L8="Hold","Hold",IF(IFERROR(E8,0)>=200,"High",IF(IFERROR(E8,0)>=100,"Medium","Normal"))) -> Normal | N8: Face + Weight Rs. 499 WhatsApp | O8: Price hook | P8: Price v4 | Q8: https://gardensuite.in/w/face-weight-499 | T8: Not sent | U8: Unknown | V8: Unknown | W8: Not offered | X8: =IF(AND(R8<>"",OR(U8="No reply",U8="Unknown")),R8+2,"") | Z8: Open | AA8: =IF(L8="Hold","Do not send",IF(T8="Not sent","Send WhatsApp",IF(U8="Demo booked","Prepare demo",IF(W8="Booked","Prepare demo",IF(AND(X8<>"",Y8=""),"Send follow-up","Review"))))) -> Send WhatsApp | AD8: =IF(AA8="Prepare demo",1,IF(AA8="Send follow-up",2,IF(AA8="Send WhatsApp",3,IF(AA8="Review",4,IF(AA8="Do not send",9,5))))) -> 3 | AE8: =IF(M8="High",1,IF(M8="Medium",2,IF(M8="Normal",3,IF(M8="Hold",9,4)))) -> 3 | AF8: =IF(T8="Read",1,IF(T8="Delivered",2,IF(T8="Sent",3,IF(T8="Not sent",4,IF(T8="Failed",9,5))))) -> 4 | AG8: =IF(U8="Demo booked",1,IF(U8="Interested",2,IF(U8="Replied",3,IF(U8="No reply",5,IF(U8="Not interested",8,IF(U8="Bad number",9,6)))))) -> 6 | AH8: =AD8*1000+AN8*100+AE8*10+AG8 -> 3136 | AI8: =MAX(IF(R8="",0,R8),IF(Y8="",0,Y8)) -> 0 | AJ8: =IF(AND(X8<>"",Y8="",X8<TODAY()),"Overdue",IF(AND(X8<>"",Y8="",X8=TODAY()),"Due today",IF(Y8<>"","Follow-up sent",""))) | AK8: Original CRM | AL8: Original CRM/manual campaign tracker | AM8: Existing CRM lead | AN8: 1 | AO8: https://wa.me/919101006460 | AP8: Login required | AQ8: 46161.628 | AR8: WhatsApp Web login required, scan QR and rerun
A9: GSW015 | B9: Dekhari T.E ( unit 1 ) | D9: 6001684868 | F9: Negotiation | G9: 46146 | H9: 46136 | I9: NOT WHATSAPP NO | K9: =IF(LEN(D9)=10,"OK","Check") -> OK | L9: =IF(ISNUMBER(SEARCH("not interested",LOWER(I9&" "&J9))),"Hold","Send") -> Send | M9: =IF(L9="Hold","Hold",IF(IFERROR(E9,0)>=200,"High",IF(IFERROR(E9,0)>=100,"Medium","Normal"))) -> Normal | N9: Face + Weight Rs. 499 WhatsApp | O9: Price hook | P9: Price v4 | Q9: https://gardensuite.in/w/face-weight-499 | T9: Not sent | U9: Unknown | V9: Unknown | W9: Not offered | X9: =IF(AND(R9<>"",OR(U9="No reply",U9="Unknown")),R9+2,"") | Z9: Open | AA9: =IF(L9="Hold","Do not send",IF(T9="Not sent","Send WhatsApp",IF(U9="Demo booked","Prepare demo",IF(W9="Booked","Prepare demo",IF(AND(X9<>"",Y9=""),"Send follow-up","Review"))))) -> Send WhatsApp | AD9: =IF(AA9="Prepare demo",1,IF(AA9="Send follow-up",2,IF(AA9="Send WhatsApp",3,IF(AA9="Review",4,IF(AA9="Do not send",9,5))))) -> 3 | AE9: =IF(M9="High",1,IF(M9="Medium",2,IF(M9="Normal",3,IF(M9="Hold",9,4)))) -> 3 | AF9: =IF(T9="Read",1,IF(T9="Delivered",2,IF(T9="Sent",3,IF(T9="Not sent",4,IF(T9="Failed",9,5))))) -> 4 | AG9: =IF(U9="Demo booked",1,IF(U9="Interested",2,IF(U9="Replied",3,IF(U9="No reply",5,IF(U9="Not interested",8,IF(U9="Bad number",9,6)))))) -> 6 | AH9: =AD9*1000+AN9*100+AE9*10+AG9 -> 3136 | AI9: =MAX(IF(R9="",0,R9),IF(Y9="",0,Y9)) -> 0 | AJ9: =IF(AND(X9<>"",Y9="",X9<TODAY()),"Overdue",IF(AND(X9<>"",Y9="",X9=TODAY()),"Due today",IF(Y9<>"","Follow-up sent",""))) | AK9: Original CRM | AL9: Original CRM/manual campaign tracker | AM9: Existing CRM lead | AN9: 1 | AO9: https://wa.me/916001684868 | AP9: Login required | AQ9: 46161.628 | AR9: WhatsApp Web login required, scan QR and rerun
A10: GSW016 | B10: Dekhari T.E ( naharani division ) unit 3 (megha T.E ) | D10: 9101006460 | F10: Negotiation | G10: 46146 | H10: 46136 | I10: INVALID NUMBER | K10: =IF(LEN(D10)=10,"OK","Check") -> OK | L10: =IF(ISNUMBER(SEARCH("not interested",LOWER(I10&" "&J10))),"Hold","Send") -> Send | M10: =IF(L10="Hold","Hold",IF(IFERROR(E10,0)>=200,"High",IF(IFERROR(E10,0)>=100,"Medium","Normal"))) -> Normal | N10: Face + Weight Rs. 499 WhatsApp | O10: Price hook | P10: Price v4 | Q10: https://gardensuite.in/w/face-weight-499 | T10: Not sent | U10: Unknown | V10: Unknown | W10: Not offered | X10: =IF(AND(R10<>"",OR(U10="No reply",U10="Unknown")),R10+2,"") | Z10: Open | AA10: =IF(L10="Hold","Do not send",IF(T10="Not sent","Send WhatsApp",IF(U10="Demo booked","Prepare demo",IF(W10="Booked","Prepare demo",IF(AND(X10<>"",Y10=""),"Send follow-up","Review"))))) -> Send WhatsApp | AD10: =IF(AA10="Prepare demo",1,IF(AA10="Send follow-up",2,IF(AA10="Send WhatsApp",3,IF(AA10="Review",4,IF(AA10="Do not send",9,5))))) -> 3 | AE10: =IF(M10="High",1,IF(M10="Medium",2,IF(M10="Normal",3,IF(M10="Hold",9,4)))) -> 3 | AF10: =IF(T10="Read",1,IF(T10="Delivered",2,IF(T10="Sent",3,IF(T10="Not sent",4,IF(T10="Failed",9,5))))) -> 4 | AG10: =IF(U10="Demo booked",1,IF(U10="Interested",2,IF(U10="Replied",3,IF(U10="No reply",5,IF(U10="Not interested",8,IF(U10="Bad number",9,6)))))) -> 6 | AH10: =AD10*1000+AN10*100+AE10*10+AG10 -> 3136 | AI10: =MAX(IF(R10="",0,R10),IF(Y10="",0,Y10)) -> 0 | AJ10: =IF(AND(X10<>"",Y10="",X10<TODAY()),"Overdue",IF(AND(X10<>"",Y10="",X10=TODAY()),"Due today",IF(Y10<>"","Follow-up sent",""))) | AK10: Original CRM | AL10: Original CRM/manual campaign tracker | AM10: Existing CRM lead | AN10: 1 | AO10: https://wa.me/919101006460 | AP10: Unchecked
A11: GSW022 | B11: Kabir T.E | D11: 8638926153 | F11: Negotiation | G11: 46148 | H11: 46139 | I11: NOT WHATSAPP NO | K11: =IF(LEN(D11)=10,"OK","Check") -> OK | L11: =IF(ISNUMBER(SEARCH("not interested",LOWER(I11&" "&J11))),"Hold","Send") -> Send | M11: =IF(L11="Hold","Hold",IF(IFERROR(E11,0)>=200,"High",IF(IFERROR(E11,0)>=100,"Medium","Normal"))) -> Normal | N11: Face + Weight Rs. 499 WhatsApp | O11: Price hook | P11: Price v4 | Q11: https://gardensuite.in/w/face-weight-499 | T11: Not sent | U11: Unknown | V11: Unknown | W11: Not offered | X11: =IF(AND(R11<>"",OR(U11="No reply",U11="Unknown")),R11+2,"") | Z11: Open | AA11: =IF(L11="Hold","Do not send",IF(T11="Not sent","Send WhatsApp",IF(U11="Demo booked","Prepare demo",IF(W11="Booked","Prepare demo",IF(AND(X11<>"",Y11=""),"Send follow-up","Review"))))) -> Send WhatsApp | AD11: =IF(AA11="Prepare demo",1,IF(AA11="Send follow-up",2,IF(AA11="Send WhatsApp",3,IF(AA11="Review",4,IF(AA11="Do not send",9,5))))) -> 3 | AE11: =IF(M11="High",1,IF(M11="Medium",2,IF(M11="Normal",3,IF(M11="Hold",9,4)))) -> 3 | AF11: =IF(T11="Read",1,IF(T11="Delivered",2,IF(T11="Sent",3,IF(T11="Not sent",4,IF(T11="Failed",9,5))))) -> 4 | AG11: =IF(U11="Demo booked",1,IF(U11="Interested",2,IF(U11="Replied",3,IF(U11="No reply",5,IF(U11="Not interested",8,IF(U11="Bad number",9,6)))))) -> 6 | AH11: =AD11*1000+AN11*100+AE11*10+AG11 -> 3136 | AI11: =MAX(IF(R11="",0,R11),IF(Y11="",0,Y11)) -> 0 | AJ11: =IF(AND(X11<>"",Y11="",X11<TODAY()),"Overdue",IF(AND(X11<>"",Y11="",X11=TODAY()),"Due today",IF(Y11<>"","Follow-up sent",""))) | AK11: Original CRM | AL11: Original CRM/manual campaign tracker | AM11: Existing CRM lead | AN11: 1 | AO11: https://wa.me/918638926153 | AP11: Login required | AQ11: 46161.629 | AR11: WhatsApp Web login required, scan QR and rerun
A12: GSW023 | B12: Longboi T.E | D12: 9395637154 | F12: Negotiation | G12: 46148 | H12: 46139 | I12: NOT WHATSAPP NO | K12: =IF(LEN(D12)=10,"OK","Check") -> OK | L12: =IF(ISNUMBER(SEARCH("not interested",LOWER(I12&" "&J12))),"Hold","Send") -> Send | M12: =IF(L12="Hold","Hold",IF(IFERROR(E12,0)>=200,"High",IF(IFERROR(E12,0)>=100,"Medium","Normal"))) -> Normal | N12: Face + Weight Rs. 499 WhatsApp | O12: Price hook | P12: Price v4 | Q12: https://gardensuite.in/w/face-weight-499 | T12: Not sent | U12: Unknown | V12: Unknown | W12: Not offered | X12: =IF(AND(R12<>"",OR(U12="No reply",U12="Unknown")),R12+2,"") | Z12: Open | AA12: =IF(L12="Hold","Do not send",IF(T12="Not sent","Send WhatsApp",IF(U12="Demo booked","Prepare demo",IF(W12="Booked","Prepare demo",IF(AND(X12<>"",Y12=""),"Send follow-up","Review"))))) -> Send WhatsApp | AD12: =IF(AA12="Prepare demo",1,IF(AA12="Send follow-up",2,IF(AA12="Send WhatsApp",3,IF(AA12="Review",4,IF(AA12="Do not send",9,5))))) -> 3 | AE12: =IF(M12="High",1,IF(M12="Medium",2,IF(M12="Normal",3,IF(M12="Hold",9,4)))) -> 3 | AF12: =IF(T12="Read",1,IF(T12="Delivered",2,IF(T12="Sent",3,IF(T12="Not sent",4,IF(T12="Failed",9,5))))) -> 4 | AG12: =IF(U12="Demo booked",1,IF(U12="Interested",2,IF(U12="Replied",3,IF(U12="No reply",5,IF(U12="Not interested",8,IF(U12="Bad number",9,6)))))) -> 6 | AH12: =AD12*1000+AN12*100+AE12*10+AG12 -> 3136 | AI12: =MAX(IF(R12="",0,R12),IF(Y12="",0,Y12)) -> 0 | AJ12: =IF(AND(X12<>"",Y12="",X12<TODAY()),"Overdue",IF(AND(X12<>"",Y12="",X12=TODAY()),"Due today",IF(Y12<>"","Follow-up sent",""))) | AK12: Original CRM | AL12: Original CRM/manual campaign tracker | AM12: Existing CRM lead | AN12: 1 | AO12: https://wa.me/919395637154 | AP12: Login required | AQ12: 46161.63 | AR12: WhatsApp Web login required, scan QR and rerun
A13: GSW025 | B13: Madhuting T.E | D13: 8876321148 | F13: Negotiation | G13: 46149 | H13: 46143 | I13: NOT WHATSAPP NO | K13: =IF(LEN(D13)=10,"OK","Check") -> OK | L13: =IF(ISNUMBER(SEARCH("not interested",LOWER(I13&" "&J13))),"Hold","Send") -> Send | M13: =IF(L13="Hold","Hold",IF(IFERROR(E13,0)>=200,"High",IF(IFERROR(E13,0)>=100,"Medium","Normal"))) -> Normal | N13: Face + Weight Rs. 499 WhatsApp | O13: Price hook | P13: Price v4 | Q13: https://gardensuite.in/w/face-weight-499 | T13: Not sent | U13: Unknown | V13: Unknown | W13: Not offered | X13: =IF(AND(R13<>"",OR(U13="No reply",U13="Unknown")),R13+2,"") | Z13: Open | AA13: =IF(L13="Hold","Do not send",IF(T13="Not sent","Send WhatsApp",IF(U13="Demo booked","Prepare demo",IF(W13="Booked","Prepare demo",IF(AND(X13<>"",Y13=""),"Send follow-up","Review"))))) -> Send WhatsApp | AD13: =IF(AA13="Prepare demo",1,IF(AA13="Send follow-up",2,IF(AA13="Send WhatsApp",3,IF(AA13="Review",4,IF(AA13="Do not send",9,5))))) -> 3 | AE13: =IF(M13="High",1,IF(M13="Medium",2,IF(M13="Normal",3,IF(M13="Hold",9,4)))) -> 3 | AF13: =IF(T13="Read",1,IF(T13="Delivered",2,IF(T13="Sent",3,IF(T13="Not sent",4,IF(T13="Failed",9,5))))) -> 4 | AG13: =IF(U13="Demo booked",1,IF(U13="Interested",2,IF(U13="Replied",3,IF(U13="No reply",5,IF(U13="Not interested",8,IF(U13="Bad number",9,6)))))) -> 6 | AH13: =AD13*1000+AN13*100+AE13*10+AG13 -> 3136 | AI13: =MAX(IF(R13="",0,R13),IF(Y13="",0,Y13)) -> 0 | AJ13: =IF(AND(X13<>"",Y13="",X13<TODAY()),"Overdue",IF(AND(X13<>"",Y13="",X13=TODAY()),"Due today",IF(Y13<>"","Follow-up sent",""))) | AK13: Original CRM | AL13: Original CRM/manual campaign tracker | AM13: Existing CRM lead | AN13: 1 | AO13: https://wa.me/918876321148 | AP13: Unchecked
A14: GSW026 | B14: Mayajan T.E | D14: 8876426227 | F14: Negotiation | G14: 46150 | H14: 46143 | I14: NOT WHATSAPP NO | K14: =IF(LEN(D14)=10,"OK","Check") -> OK | L14: =IF(ISNUMBER(SEARCH("not interested",LOWER(I14&" "&J14))),"Hold","Send") -> Send | M14: =IF(L14="Hold","Hold",IF(IFERROR(E14,0)>=200,"High",IF(IFERROR(E14,0)>=100,"Medium","Normal"))) -> Normal | N14: Face + Weight Rs. 499 WhatsApp | O14: Price hook | P14: Price v4 | Q14: https://gardensuite.in/w/face-weight-499 | T14: Not sent | U14: Unknown | V14: Unknown | W14: Not offered | X14: =IF(AND(R14<>"",OR(U14="No reply",U14="Unknown")),R14+2,"") | Z14: Open | AA14: =IF(L14="Hold","Do not send",IF(T14="Not sent","Send WhatsApp",IF(U14="Demo booked","Prepare demo",IF(W14="Booked","Prepare demo",IF(AND(X14<>"",Y14=""),"Send follow-up","Review"))))) -> Send WhatsApp | AD14: =IF(AA14="Prepare demo",1,IF(AA14="Send follow-up",2,IF(AA14="Send WhatsApp",3,IF(AA14="Review",4,IF(AA14="Do not send",9,5))))) -> 3 | AE14: =IF(M14="High",1,IF(M14="Medium",2,IF(M14="Normal",3,IF(M14="Hold",9,4)))) -> 3 | AF14: =IF(T14="Read",1,IF(T14="Delivered",2,IF(T14="Sent",3,IF(T14="Not sent",4,IF(T14="Failed",9,5))))) -> 4 | AG14: =IF(U14="Demo booked",1,IF(U14="Interested",2,IF(U14="Replied",3,IF(U14="No reply",5,IF(U14="Not interested",8,IF(U14="Bad number",9,6)))))) -> 6 | AH14: =AD14*1000+AN14*100+AE14*10+AG14 -> 3136 | AI14: =MAX(IF(R14="",0,R14),IF(Y14="",0,Y14)) -> 0 | AJ14: =IF(AND(X14<>"",Y14="",X14<TODAY()),"Overdue",IF(AND(X14<>"",Y14="",X14=TODAY()),"Due today",IF(Y14<>"","Follow-up sent",""))) | AK14: Original CRM | AL14: Original CRM/manual campaign tracker | AM14: Existing CRM lead | AN14: 1 | AO14: https://wa.me/918876426227 | AP14: Unchecked
A15: GSW027 | B15: Manoj Kunja T.E | D15: 8876426227 | F15: Negotiation | G15: 46150 | H15: 46143 | I15: NOT WHATSAPP NO | K15: =IF(LEN(D15)=10,"OK","Check") -> OK | L15: =IF(ISNUMBER(SEARCH("not interested",LOWER(I15&" "&J15))),"Hold","Send") -> Send | M15: =IF(L15="Hold","Hold",IF(IFERROR(E15,0)>=200,"High",IF(IFERROR(E15,0)>=100,"Medium","Normal"))) -> Normal | N15: Face + Weight Rs. 499 WhatsApp | O15: Price hook | P15: Price v4 | Q15: https://gardensuite.in/w/face-weight-499 | T15: Not sent | U15: Unknown | V15: Unknown | W15: Not offered | X15: =IF(AND(R15<>"",OR(U15="No reply",U15="Unknown")),R15+2,"") | Z15: Open | AA15: =IF(L15="Hold","Do not send",IF(T15="Not sent","Send WhatsApp",IF(U15="Demo booked","Prepare demo",IF(W15="Booked","Prepare demo",IF(AND(X15<>"",Y15=""),"Send follow-up","Review"))))) -> Send WhatsApp | AD15: =IF(AA15="Prepare demo",1,IF(AA15="Send follow-up",2,IF(AA15="Send WhatsApp",3,IF(AA15="Review",4,IF(AA15="Do not send",9,5))))) -> 3 | AE15: =IF(M15="High",1,IF(M15="Medium",2,IF(M15="Normal",3,IF(M15="Hold",9,4)))) -> 3 | AF15: =IF(T15="Read",1,IF(T15="Delivered",2,IF(T15="Sent",3,IF(T15="Not sent",4,IF(T15="Failed",9,5))))) -> 4 | AG15: =IF(U15="Demo booked",1,IF(U15="Interested",2,IF(U15="Replied",3,IF(U15="No reply",5,IF(U15="Not interested",8,IF(U15="Bad number",9,6)))))) -> 6 | AH15: =AD15*1000+AN15*100+AE15*10+AG15 -> 3136 | AI15: =MAX(IF(R15="",0,R15),IF(Y15="",0,Y15)) -> 0 | AJ15: =IF(AND(X15<>"",Y15="",X15<TODAY()),"Overdue",IF(AND(X15<>"",Y15="",X15=TODAY()),"Due today",IF(Y15<>"","Follow-up sent",""))) | AK15: Original CRM | AL15: Original CRM/manual campaign tracker | AM15: Existing CRM lead | AN15: 1 | AO15: https://wa.me/918876426227 | AP15: Unchecked
